<?xml version="1.0" ?>
<sdf version="1.4">
  <model name="universal-picker">
    <pose>0 0 0.09 0 0 0</pose>
    <link name="base_footprint">
      <pose>0 0 0 0 0 0</pose>
      <inertial>
        <pose>0 0 -0.050000 0 0 0</pose>
        <inertia>
          <ixx>1</ixx>
          <ixy>0</ixy>
          <ixz>0</ixz>
          <iyy>1</iyy>
          <iyz>0</iyz>
          <izz>1</izz>
        </inertia>
        <mass>0.100000</mass>
      </inertial>
      <collision name="base_footprint_geom">
        <pose>0 0 -0.050000 0 0 0</pose>
        <geometry>
          <box>
            <size>0.001000 0.001000 0.001000</size>
          </box>
        </geometry>
        <surface>
          <friction>
            <ode>
              <mu>0</mu>
              <mu2>0</mu2>
              <fdir1>0 0 0</fdir1>
              <slip1>0</slip1>
              <slip2>0</slip2>
            </ode>
          </friction>
          <bounce>
            <restitution_coefficient>0</restitution_coefficient>
            <threshold>0</threshold>
          </bounce>
          <contact>
            <ode>
              <soft_cfm>0</soft_cfm>
              <soft_erp>0.200000</soft_erp>
              <kp>10000000000000.000000</kp>
              <kd>100000000000.000000</kd>
              <max_vel>-1</max_vel>
              <min_depth>0</min_depth>
            </ode>
          </contact>
        </surface>
        <laser_retro>0</laser_retro>
      </collision>
      <visual name="base_footprint_geom_visual">
        <pose>0 0 0 0 0 0</pose>
        <geometry>
          <box>
            <size>0.001000 0.001000 0.001000</size>
          </box>
        </geometry>
      </visual>
      <gravity>1</gravity>
      <self_collide>0</self_collide>
      <kinematic>0</kinematic>
    </link>
    <link name="base_link">
      <pose>0 0 0 0 0 0</pose>
      <gravity>0</gravity>
      <self_collide>0</self_collide>
      <kinematic>0</kinematic>
    </link>
    <link name="base_laser_front_link">
      <pose>0.300000 0 -0.030000 0 0 0</pose>
      <inertial>
        <pose>0 0 0 0 0 0</pose>
        <inertia>
          <ixx>0.100000</ixx>
          <ixy>0</ixy>
          <ixz>0</ixz>
          <iyy>0.100000</iyy>
          <iyz>0</iyz>
          <izz>0.100000</izz>
        </inertia>
        <mass>0.160000</mass>
      </inertial>
      <collision name="base_laser_front_link_geom">
        <pose>0 0 0 0 0 0</pose>
        <geometry>
          <mesh>
            <uri>model://hokuyo/meshes/hokuyo_convex.stl</uri>
          </mesh>
        </geometry>
        <surface>
          <friction>
            <ode>
              <mu>0</mu>
              <mu2>0</mu2>
              <fdir1>0 0 0</fdir1>
              <slip1>0</slip1>
              <slip2>0</slip2>
            </ode>
          </friction>
          <bounce>
            <restitution_coefficient>0</restitution_coefficient>
            <threshold>0</threshold>
          </bounce>
          <contact>
            <ode>
              <soft_cfm>0</soft_cfm>
              <soft_erp>0.200000</soft_erp>
              <kp>10000000000000.000000</kp>
              <kd>100000000000.000000</kd>
              <max_vel>-1</max_vel>
              <min_depth>0</min_depth>
            </ode>
          </contact>
        </surface>
        <laser_retro>0</laser_retro>
      </collision>
      <visual name="base_laser_front_link_geom_visual">
        <pose>0 0 0 0 0 0</pose>
        <geometry>
          <mesh>
            <uri>model://hokuyo/meshes/hokuyo.dae</uri>
          </mesh>
        </geometry>
      </visual>
      <sensor name="base_laser_front" type="ray">
        <pose>0 0 0 0 0 0</pose>
        <ray>
          <scan>
            <horizontal>
              <samples>640</samples>
              <resolution>1</resolution>
              <min_angle>-1.570000</min_angle>
              <max_angle>1.570000</max_angle>
            </horizontal>
          </scan>
          <range>
            <min>0.050000</min>
            <max>5.600000</max>
            <resolution>0.360000</resolution>
          </range>
        </ray>
        <always_on>0</always_on>
        <update_rate>10.000000</update_rate>
        <visualize>0</visualize>
      </sensor>
      <gravity>1</gravity>
      <self_collide>0</self_collide>
      <kinematic>0</kinematic>
    </link>
    <link name="caster_link_bl">
      <pose>-0.228000 0.158000 -0.034000 0 0 0</pose>
      <inertial>
        <pose>0 0 0 0 0 0</pose>
        <inertia>
          <ixx>0.012412</ixx>
          <ixy>-0.000712</ixy>
          <ixz>0.000503</ixz>
          <iyy>0.015218</iyy>
          <iyz>-0.000004</iyz>
          <izz>0.011764</izz>
        </inertia>
        <mass>0.100000</mass>
      </inertial>
      <gravity>1</gravity>
      <self_collide>0</self_collide>
      <kinematic>0</kinematic>
    </link>
    <link name="wheel_link_bl">
      <pose>-0.228000 0.158000 -0.034000 0 0 0</pose>
      <inertial>
        <pose>0 0 0 0 0 0</pose>
        <inertia>
          <ixx>0.012412</ixx>
          <ixy>-0.000712</ixy>
          <ixz>0.000503</ixz>
          <iyy>0.015218</iyy>
          <iyz>-0.000004</iyz>
          <izz>0.011764</izz>
        </inertia>
        <mass>0.400000</mass>
      </inertial>
      <collision name="wheel_link_bl_geom">
        <pose>0 0 0 1.570800 0 0</pose>
        <geometry>
          <cylinder>
            <radius>0.050000</radius>
            <length>0.005000</length>
          </cylinder>
        </geometry>
        <surface>
          <friction>
            <ode>
              <mu>0</mu>
              <mu2>0</mu2>
              <fdir1>0 0 0</fdir1>
              <slip1>0</slip1>
              <slip2>0</slip2>
            </ode>
          </friction>
          <bounce>
            <restitution_coefficient>0</restitution_coefficient>
            <threshold>0</threshold>
          </bounce>
          <contact>
            <ode>
              <soft_cfm>0</soft_cfm>
              <soft_erp>0.200000</soft_erp>
              <kp>10000000000000.000000</kp>
              <kd>100000000000.000000</kd>
              <max_vel>-1</max_vel>
              <min_depth>0</min_depth>
            </ode>
          </contact>
        </surface>
        <laser_retro>0</laser_retro>
      </collision>
      <visual name="wheel_link_bl_geom_visual">
        <pose>0 0 0 0 0 0</pose>
        <geometry>
          <mesh>
            <uri>model://youbot/meshes/base/back-left_wheel.dae</uri>
          </mesh>
        </geometry>
        <material>
          <script>
            <uri>model://youbot/materials/scripts/youbot.material</uri>
            <name>youbot/Orange</name>
          </script>
        </material>
      </visual>
      <gravity>1</gravity>
      <self_collide>0</self_collide>
      <kinematic>0</kinematic>
    </link>
    <link name="caster_link_br">
      <pose>-0.228000 -0.158000 -0.034000 0 0 0</pose>
      <inertial>
        <pose>0 0 0 0 0 0</pose>
        <inertia>
          <ixx>0.012412</ixx>
          <ixy>-0.000712</ixy>
          <ixz>0.000503</ixz>
          <iyy>0.015218</iyy>
          <iyz>-0.000004</iyz>
          <izz>0.011764</izz>
        </inertia>
        <mass>0.100000</mass>
      </inertial>
      <gravity>1</gravity>
      <self_collide>0</self_collide>
      <kinematic>0</kinematic>
    </link>
    <link name="wheel_link_br">
      <pose>-0.228000 -0.158000 -0.034000 0 0 0</pose>
      <inertial>
        <pose>0 0 0 0 0 0</pose>
        <inertia>
          <ixx>0.012412</ixx>
          <ixy>-0.000712</ixy>
          <ixz>0.000503</ixz>
          <iyy>0.015218</iyy>
          <iyz>-0.000004</iyz>
          <izz>0.011764</izz>
        </inertia>
        <mass>0.400000</mass>
      </inertial>
      <collision name="wheel_link_br_geom">
        <pose>0 0 0 1.570800 0 0</pose>
        <geometry>
          <cylinder>
            <radius>0.050000</radius>
            <length>0.005000</length>
          </cylinder>
        </geometry>
        <surface>
          <friction>
            <ode>
              <mu>0</mu>
              <mu2>0</mu2>
              <fdir1>0 0 0</fdir1>
              <slip1>0</slip1>
              <slip2>0</slip2>
            </ode>
          </friction>
          <bounce>
            <restitution_coefficient>0</restitution_coefficient>
            <threshold>0</threshold>
          </bounce>
          <contact>
            <ode>
              <soft_cfm>0</soft_cfm>
              <soft_erp>0.200000</soft_erp>
              <kp>10000000000000.000000</kp>
              <kd>100000000000.000000</kd>
              <max_vel>-1</max_vel>
              <min_depth>0</min_depth>
            </ode>
          </contact>
        </surface>
        <laser_retro>0</laser_retro>
      </collision>
      <visual name="wheel_link_br_geom_visual">
        <pose>0 0 0 0 0 0</pose>
        <geometry>
          <mesh>
            <uri>model://youbot/meshes/base/back-right_wheel.dae</uri>
          </mesh>
        </geometry>
        <material>
          <script>
            <uri>model://youbot/materials/scripts/youbot.material</uri>
            <name>youbot/Orange</name>
          </script>
        </material>
      </visual>
      <gravity>1</gravity>
      <self_collide>0</self_collide>
      <kinematic>0</kinematic>
    </link>
    <link name="caster_link_fl">
      <pose>0.228000 0.158000 -0.034000 0 0 0</pose>
      <inertial>
        <pose>0 0 0 0 0 0</pose>
        <inertia>
          <ixx>0.012412</ixx>
          <ixy>-0.000712</ixy>
          <ixz>0.000503</ixz>
          <iyy>0.015218</iyy>
          <iyz>-0.000004</iyz>
          <izz>0.011764</izz>
        </inertia>
        <mass>0.100000</mass>
      </inertial>
      <gravity>1</gravity>
      <self_collide>0</self_collide>
      <kinematic>0</kinematic>
    </link>
    <link name="wheel_link_fl">
      <pose>0.228000 0.158000 -0.034000 0 0 0</pose>
      <inertial>
        <pose>0 0 0 0 0 0</pose>
        <inertia>
          <ixx>0.012412</ixx>
          <ixy>-0.000712</ixy>
          <ixz>0.000503</ixz>
          <iyy>0.015218</iyy>
          <iyz>-0.000004</iyz>
          <izz>0.011764</izz>
        </inertia>
        <mass>0.400000</mass>
      </inertial>
      <collision name="wheel_link_fl_geom">
        <pose>0 0 0 1.570800 0 0</pose>
        <geometry>
          <cylinder>
            <radius>0.050000</radius>
            <length>0.005000</length>
          </cylinder>
        </geometry>
        <surface>
          <friction>
            <ode>
              <mu>0</mu>
              <mu2>0</mu2>
              <fdir1>0 0 0</fdir1>
              <slip1>0</slip1>
              <slip2>0</slip2>
            </ode>
          </friction>
          <bounce>
            <restitution_coefficient>0</restitution_coefficient>
            <threshold>0</threshold>
          </bounce>
          <contact>
            <ode>
              <soft_cfm>0</soft_cfm>
              <soft_erp>0.200000</soft_erp>
              <kp>10000000000000.000000</kp>
              <kd>100000000000.000000</kd>
              <max_vel>-1</max_vel>
              <min_depth>0</min_depth>
            </ode>
          </contact>
        </surface>
        <laser_retro>0</laser_retro>
      </collision>
      <visual name="wheel_link_fl_geom_visual">
        <pose>0 0 0 0 0 0</pose>
        <geometry>
          <mesh>
            <uri>model://youbot/meshes/base/front-left_wheel.dae</uri>
          </mesh>
        </geometry>
        <material>
          <script>
            <uri>model://youbot/materials/scripts/youbot.material</uri>
            <name>youbot/Orange</name>
          </script>
        </material>
      </visual>
      <gravity>1</gravity>
      <self_collide>0</self_collide>
      <kinematic>0</kinematic>
    </link>
    <link name="caster_link_fr">
      <pose>0.228000 -0.158000 -0.034000 0 0 0</pose>
      <inertial>
        <pose>0 0 0 0 0 0</pose>
        <inertia>
          <ixx>0.012412</ixx>
          <ixy>-0.000712</ixy>
          <ixz>0.000503</ixz>
          <iyy>0.015218</iyy>
          <iyz>-0.000004</iyz>
          <izz>0.011764</izz>
        </inertia>
        <mass>0.100000</mass>
      </inertial>
      <gravity>1</gravity>
      <self_collide>0</self_collide>
      <kinematic>0</kinematic>
    </link>
    <link name="wheel_link_fr">
      <pose>0.228000 -0.158000 -0.034000 0 0 0</pose>
      <inertial>
        <pose>0 0 0 0 0 0</pose>
        <inertia>
          <ixx>0.012412</ixx>
          <ixy>-0.000712</ixy>
          <ixz>0.000503</ixz>
          <iyy>0.015218</iyy>
          <iyz>-0.000004</iyz>
          <izz>0.011764</izz>
        </inertia>
        <mass>0.400000</mass>
      </inertial>
      <collision name="wheel_link_fr_geom">
        <pose>0 0 0 1.570800 0 0</pose>
        <geometry>
          <cylinder>
            <radius>0.050000</radius>
            <length>0.005000</length>
          </cylinder>
        </geometry>
        <surface>
          <friction>
            <ode>
              <mu>0</mu>
              <mu2>0</mu2>
              <fdir1>0 0 0</fdir1>
              <slip1>0</slip1>
              <slip2>0</slip2>
            </ode>
          </friction>
          <bounce>
            <restitution_coefficient>0</restitution_coefficient>
            <threshold>0</threshold>
          </bounce>
          <contact>
            <ode>
              <soft_cfm>0</soft_cfm>
              <soft_erp>0.200000</soft_erp>
              <kp>10000000000000.000000</kp>
              <kd>100000000000.000000</kd>
              <max_vel>-1</max_vel>
              <min_depth>0</min_depth>
            </ode>
          </contact>
        </surface>
        <laser_retro>0</laser_retro>
      </collision>
      <visual name="wheel_link_fr_geom_visual">
        <pose>0 0 0 0 0 0</pose>
        <geometry>
          <mesh>
            <uri>model://youbot/meshes/base/front-right_wheel.dae</uri>
          </mesh>
        </geometry>
        <material>
          <script>
            <uri>model://youbot/materials/scripts/youbot.material</uri>
            <name>youbot/Orange</name>
          </script>
        </material>
      </visual>
      <gravity>1</gravity>
      <self_collide>0</self_collide>
      <kinematic>0</kinematic>
    </link>
<!-- PR2 Gripper   --> 
    <link name='r_wrist_roll_link'>
      <!--pose>0.771000 -0.188000 0.790675 0.000000 -0.000000 0.000000</pose-->
      <pose>-0.250000 0.0000000 1.3 0.000000 0.000000 0.000000</pose>
     <inertial>
        <pose>0.056408 0.000451 -0.001014 0.000000 -0.000000 0.000000</pose>
        <inertia>
          <ixx>0.011352</ixx>
          <ixy>-0.000016</ixy>
          <ixz>-0.000001</ixz>
          <iyy>0.011677</iyy>
          <iyz>-0.000001</iyz>
          <izz>0.011866</izz>
        </inertia>
        <mass>0.681070</mass>
      </inertial>
      <collision name='r_wrist_roll_link_geom'>
        <pose>0.000000 0.000000 0.000000 0.000000 -0.000000 0.000000</pose>
        <geometry>
          <mesh>
            <uri>model://pr2/meshes/forearm_v0/wrist_roll_L.stl</uri>
            <scale>1.000000 1.000000 1.000000</scale>
            <uri>__default__</uri>
          </mesh>
        </geometry>
        <surface>
          <friction>
            <ode>
              <mu>-1.000000</mu>
              <mu2>-1.000000</mu2>
              <fdir1>0.000000 0.000000 0.000000</fdir1>
              <slip1>0.000000</slip1>
              <slip2>0.000000</slip2>
            </ode>
          </friction>
          <bounce>
            <restitution_coefficient>0.000000</restitution_coefficient>
            <threshold>100000.000000</threshold>
          </bounce>
          <contact>
            <ode>
              <soft_cfm>0.000000</soft_cfm>
              <soft_erp>0.200000</soft_erp>
              <kp>1000000000000.000000</kp>
              <kd>1.000000</kd>
              <max_vel>0.000000</max_vel>
              <min_depth>0.001000</min_depth>
            </ode>
          </contact>
        </surface>
        <laser_retro>0.000000</laser_retro>
      </collision>
      <visual name='r_wrist_roll_link_geom_visual'>
        <pose>0.000000 0.000000 0.000000 0.000000 -0.000000 0.000000</pose>
        <geometry>
          <mesh>
            <uri>model://pr2/meshes/forearm_v0/wrist_roll.stl</uri>
            <scale>1.000000 1.000000 1.000000</scale>
            <uri>__default__</uri>
          </mesh>
        </geometry>
        <material>
          <script>
            <name>__default__</name>
          </script>
        </material>
        <cast_shadows>1</cast_shadows>
        <laser_retro>0.000000</laser_retro>
        <transparency>0.000000</transparency>
      </visual>
      <visual name='r_wrist_roll_link_geom_r_gripper_palm_link_visual'>
        <pose>0.000000 0.000000 0.000000 0.000000 -0.000000 0.000000</pose>
        <geometry>
          <mesh>
            <uri>model://pr2/meshes/gripper_v0/gripper_palm.dae</uri>
            <scale>1.000000 1.000000 1.000000</scale>
            <uri>__default__</uri>
          </mesh>
        </geometry>
        <cast_shadows>1</cast_shadows>
        <laser_retro>0.000000</laser_retro>
        <transparency>0.000000</transparency>
      </visual>
      <gravity>1</gravity>
      <self_collide>0</self_collide>
      <kinematic>0</kinematic>
      <velocity_decay/>
    </link>
    <link name='r_gripper_l_finger_link'>
      <pose>0.847910 -0.178000 0.790675 0.000000 -0.000000 0.000000</pose>
      <inertial>
        <pose>0.035980 0.017300 -0.001640 0.000000 -0.000000 0.000000</pose>
        <inertia>
          <ixx>0.000078</ixx>
          <ixy>0.000001</ixy>
          <ixz>-0.000010</ixz>
          <iyy>0.000197</iyy>
          <iyz>-0.000003</iyz>
          <izz>0.000181</izz>
        </inertia>
        <mass>0.171260</mass>
      </inertial>
      <collision name='r_gripper_l_finger_link_geom'>
        <pose>0.000000 0.000000 0.000000 0.000000 -0.000000 0.000000</pose>
        <geometry>
          <mesh>
            <uri>model://pr2/meshes/gripper_v0/l_finger.stl</uri>
            <scale>1.000000 1.000000 1.000000</scale>
            <uri>__default__</uri>
          </mesh>
        </geometry>
        <surface>
          <friction>
            <ode>
              <mu>500.000000</mu>
              <mu2>500.000000</mu2>
              <fdir1>0.000000 0.000000 0.000000</fdir1>
              <slip1>0.000000</slip1>
              <slip2>0.000000</slip2>
            </ode>
          </friction>
          <bounce>
            <restitution_coefficient>0.000000</restitution_coefficient>
            <threshold>100000.000000</threshold>
          </bounce>
          <contact>
            <ode>
              <soft_cfm>0.000000</soft_cfm>
              <soft_erp>0.200000</soft_erp>
              <kp>1000000.000000</kp>
              <kd>1.000000</kd>
              <max_vel>0.000000</max_vel>
              <min_depth>0.001000</min_depth>
            </ode>
          </contact>
        </surface>
        <laser_retro>0.000000</laser_retro>
      </collision>
      <visual name='r_gripper_l_finger_link_geom_visual'>
        <pose>0.000000 0.000000 0.000000 0.000000 -0.000000 0.000000</pose>
        <geometry>
          <mesh>
            <uri>model://pr2/meshes/gripper_v0/l_finger.dae</uri>
            <scale>1.000000 1.000000 1.000000</scale>
            <uri>__default__</uri>
          </mesh>
        </geometry>
        <cast_shadows>1</cast_shadows>
        <laser_retro>0.000000</laser_retro>
        <transparency>0.000000</transparency>
      </visual>
      <gravity>1</gravity>
      <self_collide>0</self_collide>
      <kinematic>0</kinematic>
      <velocity_decay/>
    </link>
    <link name='r_gripper_l_finger_tip_link'>
      <pose>0.939280 -0.173050 0.790675 0.000000 -0.000000 0.000000</pose>
      <inertial>
        <pose>0.004230 0.002840 0.000000 0.000000 -0.000000 0.000000</pose>
        <inertia>
          <ixx>0.000008</ixx>
          <ixy>0.000006</ixy>
          <ixz>0.000000</ixz>
          <iyy>0.000010</iyy>
          <iyz>0.000000</iyz>
          <izz>0.000015</izz>
        </inertia>
        <mass>0.044190</mass>
      </inertial>
      <collision name='r_gripper_l_finger_tip_link_geom'>
        <pose>0.000000 0.000000 0.000000 0.000000 -0.000000 0.000000</pose>
        <geometry>
          <mesh>
            <uri>model://pr2/meshes/gripper_v0/l_finger_tip.stl</uri>
            <scale>1.000000 1.000000 1.000000</scale>
            <uri>__default__</uri>
          </mesh>
        </geometry>
        <surface>
          <friction>
            <ode>
              <mu>500.000000</mu>
              <mu2>500.000000</mu2>
              <fdir1>0.000000 0.000000 0.000000</fdir1>
              <slip1>0.000000</slip1>
              <slip2>0.000000</slip2>
            </ode>
          </friction>
          <bounce>
            <restitution_coefficient>0.000000</restitution_coefficient>
            <threshold>100000.000000</threshold>
          </bounce>
          <contact>
            <ode>
              <soft_cfm>0.000000</soft_cfm>
              <soft_erp>0.200000</soft_erp>
              <kp>10000000.000000</kp>
              <kd>1.000000</kd>
              <max_vel>0.000000</max_vel>
              <min_depth>0.001000</min_depth>
            </ode>
          </contact>
        </surface>
        <laser_retro>0.000000</laser_retro>
      </collision>
      <visual name='r_gripper_l_finger_tip_link_geom_visual'>
        <pose>0.000000 0.000000 0.000000 0.000000 -0.000000 0.000000</pose>
        <geometry>
          <mesh>
            <uri>model://pr2/meshes/gripper_v0/l_finger_tip.dae</uri>
            <scale>1.000000 1.000000 1.000000</scale>
            <uri>__default__</uri>
          </mesh>
        </geometry>
        <cast_shadows>1</cast_shadows>
        <laser_retro>0.000000</laser_retro>
        <transparency>0.000000</transparency>
      </visual>
      <sensor name='r_gripper_l_finger_tip_contact_sensor' type='contact'>
        <pose>0.000000 0.000000 0.000000 0.000000 -0.000000 0.000000</pose>
        <contact>
          <collision>r_gripper_l_finger_tip_link_geom</collision>
          <topic>__default_topic__</topic>
        </contact>
        <always_on>0</always_on>
        <update_rate>100.000000</update_rate>
        <visualize>0</visualize>
      </sensor>
      <gravity>1</gravity>
      <self_collide>0</self_collide>
      <kinematic>0</kinematic>
      <velocity_decay/>
    </link>
    <link name='r_gripper_motor_slider_link'>
      <pose>0.939280 -0.188000 0.790675 0.000000 -0.000000 0.000000</pose>
      <inertial>
        <pose>0.000000 0.000000 0.000000 0.000000 -0.000000 0.000000</pose>
        <inertia>
          <ixx>0.001000</ixx>
          <ixy>0.000000</ixy>
          <ixz>0.000000</ixz>
          <iyy>0.001000</iyy>
          <iyz>0.000000</iyz>
          <izz>0.001000</izz>
        </inertia>
        <mass>0.010000</mass>
      </inertial>
      <gravity>1</gravity>
      <self_collide>0</self_collide>
      <kinematic>0</kinematic>
      <velocity_decay/>
    </link>
    <link name='r_gripper_motor_screw_link'>
      <pose>0.939280 -0.188000 0.790675 0.000000 -0.000000 0.000000</pose>
      <inertial>
        <pose>0.000000 0.000000 0.000000 0.000000 -0.000000 0.000000</pose>
        <inertia>
          <ixx>0.000100</ixx>
          <ixy>0.000000</ixy>
          <ixz>0.000000</ixz>
          <iyy>0.000100</iyy>
          <iyz>0.000000</iyz>
          <izz>0.000100</izz>
        </inertia>
        <mass>0.010000</mass>
      </inertial>
      <gravity>1</gravity>
      <self_collide>0</self_collide>
      <kinematic>0</kinematic>
      <velocity_decay/>
    </link>
    <link name='r_gripper_r_finger_link'>
      <pose>0.847910 -0.198000 0.790675 0.000000 -0.000000 0.000000</pose>
      <inertial>
        <pose>0.035760 -0.017360 -0.000950 0.000000 -0.000000 0.000000</pose>
        <inertia>
          <ixx>0.000077</ixx>
          <ixy>-0.000002</ixy>
          <ixz>-0.000008</ixz>
          <iyy>0.000198</iyy>
          <iyz>0.000002</iyz>
          <izz>0.000181</izz>
        </inertia>
        <mass>0.173890</mass>
      </inertial>
      <collision name='r_gripper_r_finger_link_geom'>
        <pose>0.000000 0.000000 0.000000 -3.141590 -0.000000 0.000000</pose>
        <geometry>
          <mesh>
            <uri>model://pr2/meshes/gripper_v0/l_finger.stl</uri>
            <scale>1.000000 1.000000 1.000000</scale>
            <uri>__default__</uri>
          </mesh>
        </geometry>
        <surface>
          <friction>
            <ode>
              <mu>500.000000</mu>
              <mu2>500.000000</mu2>
              <fdir1>0.000000 0.000000 0.000000</fdir1>
              <slip1>0.000000</slip1>
              <slip2>0.000000</slip2>
            </ode>
          </friction>
          <bounce>
            <restitution_coefficient>0.000000</restitution_coefficient>
            <threshold>100000.000000</threshold>
          </bounce>
          <contact>
            <ode>
              <soft_cfm>0.000000</soft_cfm>
              <soft_erp>0.200000</soft_erp>
              <kp>1000000.000000</kp>
              <kd>1.000000</kd>
              <max_vel>0.000000</max_vel>
              <min_depth>0.001000</min_depth>
            </ode>
          </contact>
        </surface>
        <laser_retro>0.000000</laser_retro>
      </collision>
      <visual name='r_gripper_r_finger_link_geom_visual'>
        <pose>0.000000 0.000000 0.000000 -3.141590 0.000000 0.000000</pose>
        <geometry>
          <mesh>
            <uri>model://pr2/meshes/gripper_v0/l_finger.dae</uri>
            <scale>1.000000 1.000000 1.000000</scale>
            <uri>__default__</uri>
          </mesh>
        </geometry>
        <cast_shadows>1</cast_shadows>
        <laser_retro>0.000000</laser_retro>
        <transparency>0.000000</transparency>
      </visual>
      <gravity>1</gravity>
      <self_collide>0</self_collide>
      <kinematic>0</kinematic>
      <velocity_decay/>
    </link>
    <link name='r_gripper_r_finger_tip_link'>
      <pose>0.939280 -0.202950 0.790675 0.000000 -0.000000 0.000000</pose>
      <inertial>
        <pose>0.004230 -0.002840 0.000000 0.000000 -0.000000 0.000000</pose>
        <inertia>
          <ixx>0.000008</ixx>
          <ixy>-0.000006</ixy>
          <ixz>0.000000</ixz>
          <iyy>0.000010</iyy>
          <iyz>0.000000</iyz>
          <izz>0.000015</izz>
        </inertia>
        <mass>0.044190</mass>
      </inertial>
      <collision name='r_gripper_r_finger_tip_link_geom'>
        <pose>0.000000 0.000000 0.000000 -3.141590 -0.000000 0.000000</pose>
        <geometry>
          <mesh>
            <uri>model://pr2/meshes/gripper_v0/l_finger_tip.stl</uri>
            <scale>1.000000 1.000000 1.000000</scale>
            <uri>__default__</uri>
          </mesh>
        </geometry>
        <surface>
          <friction>
            <ode>
              <mu>500.000000</mu>
              <mu2>500.000000</mu2>
              <fdir1>0.000000 0.000000 0.000000</fdir1>
              <slip1>0.000000</slip1>
              <slip2>0.000000</slip2>
            </ode>
          </friction>
          <bounce>
            <restitution_coefficient>0.000000</restitution_coefficient>
            <threshold>100000.000000</threshold>
          </bounce>
          <contact>
            <ode>
              <soft_cfm>0.000000</soft_cfm>
              <soft_erp>0.200000</soft_erp>
              <kp>10000000.000000</kp>
              <kd>1.000000</kd>
              <max_vel>0.000000</max_vel>
              <min_depth>0.001000</min_depth>
            </ode>
          </contact>
        </surface>
        <laser_retro>0.000000</laser_retro>
      </collision>
      <visual name='r_gripper_r_finger_tip_link_geom_visual'>
        <pose>0.000000 0.000000 0.000000 -3.141590 0.000000 0.000000</pose>
        <geometry>
          <mesh>
            <uri>model://pr2/meshes/gripper_v0/l_finger_tip.dae</uri>
            <scale>1.000000 1.000000 1.000000</scale>
            <uri>__default__</uri>
          </mesh>
        </geometry>
        <cast_shadows>1</cast_shadows>
        <laser_retro>0.000000</laser_retro>
        <transparency>0.000000</transparency>
      </visual>
      <sensor name='r_gripper_r_finger_tip_contact_sensor' type='contact'>
        <pose>0.000000 0.000000 0.000000 0.000000 -0.000000 0.000000</pose>
        <contact>
          <collision>r_gripper_r_finger_tip_link_geom</collision>
          <topic>__default_topic__</topic>
        </contact>
        <always_on>0</always_on>
        <update_rate>100.000000</update_rate>
        <visualize>0</visualize>
      </sensor>
      <gravity>1</gravity>
      <self_collide>0</self_collide>
      <kinematic>0</kinematic>
      <velocity_decay/>
    </link>
    <link name='torso_lift_motor_screw_link'>
      <pose>-0.150000 0.000000 0.751000 0.000000 -0.000000 0.000000</pose>
      <inertial>
        <pose>0.000000 0.000000 0.000000 0.000000 -0.000000 0.000000</pose>
        <inertia>
          <ixx>0.001000</ixx>
          <ixy>0.000000</ixy>
          <ixz>0.000000</ixz>
          <iyy>0.001000</iyy>
          <iyz>0.000000</iyz>
          <izz>0.001000</izz>
        </inertia>
        <mass>1.000000</mass>
      </inertial>
      <gravity>1</gravity>
      <self_collide>0</self_collide>
      <kinematic>0</kinematic>
      <velocity_decay/>
    </link>
    <link name='r_gripper_l_parallel_link'>
      <!--pose>0.829910 -0.157000 0.790675 0.000000 -0.000000 0.000000</pose-->
      
      <inertial>
        <pose>0.035980 0.017300 -0.001640 0.000000 -0.000000 0.000000</pose>
        <inertia>
          <ixx>0.000078</ixx>
          <ixy>0.000001</ixy>
          <ixz>-0.000010</ixz>
          <iyy>0.000197</iyy>
          <iyz>-0.000003</iyz>
          <izz>0.000181</izz>
        </inertia>
        <mass>0.171260</mass>
      </inertial>
      <gravity>1</gravity>
      <self_collide>0</self_collide>
      <kinematic>0</kinematic>
      <velocity_decay/>
    </link>
    <link name='r_gripper_r_parallel_link'>
      <!--pose>0.829910 -0.219000 0.790675 0.000000 -0.000000 0.000000</pose-->
     
      <inertial>
        <pose>0.035760 -0.017360 -0.000950 0.000000 -0.000000 0.000000</pose>
        <inertia>
          <ixx>0.000077</ixx>
          <ixy>-0.000002</ixy>
          <ixz>-0.000008</ixz>
          <iyy>0.000198</iyy>
          <iyz>0.000002</iyz>
          <izz>0.000181</izz>
        </inertia>
        <mass>0.173890</mass>
      </inertial>
      <gravity>1</gravity>
      <self_collide>0</self_collide>
      <kinematic>0</kinematic>
      <velocity_decay/>
    </link>
    <joint name='r_gripper_l_finger_joint' type='revolute'>
      <pose>0.000000 0.000000 0.000000 0.000000 -0.000000 0.000000</pose>
      <parent>r_wrist_roll_link</parent>
      <child>r_gripper_l_finger_link</child>
      <axis>
        <dynamics>
          <damping>0.020000</damping>
          <friction>0.000000</friction>
        </dynamics>
        <limit>
          <lower>0.000000</lower>
          <upper>0.548000</upper>
          <effort>0.000000</effort>
          <velocity>0.000000</velocity>
        </limit>
        <xyz>0.000000 0.000000 1.000000</xyz>
      </axis>
    </joint>
    <joint name='r_gripper_l_finger_tip_joint' type='revolute'>
      <pose>0.000000 0.000000 0.000000 0.000000 -0.000000 0.000000</pose>
      <parent>r_gripper_l_finger_link</parent>
      <child>r_gripper_l_finger_tip_link</child>
      <axis>
        <dynamics>
          <damping>0.001000</damping>
          <friction>0.000000</friction>
        </dynamics>
        <limit>
          <lower>0.000000</lower>
          <upper>0.548000</upper>
          <effort>0.000000</effort>
          <velocity>0.000000</velocity>
        </limit>
        <xyz>0.000000 0.000000 -1.000000</xyz>
      </axis>
    </joint>
    <joint name='r_gripper_motor_slider_joint' type='prismatic'>
      <pose>0.000000 0.000000 0.000000 0.000000 -0.000000 0.000000</pose>
      <parent>r_wrist_roll_link</parent>
      <child>r_gripper_motor_slider_link</child>
      <axis>
        <dynamics>
          <damping>0.000000</damping>
          <friction>0.000000</friction>
        </dynamics>
        <limit>
          <lower>-0.100000</lower>
          <upper>0.100000</upper>
          <effort>0.000000</effort>
          <velocity>0.000000</velocity>
        </limit>
        <xyz>1.000000 0.000000 0.000000</xyz>
      </axis>
    </joint>
    <joint name='r_gripper_motor_screw_joint' type='revolute'>
      <pose>0.000000 0.000000 0.000000 0.000000 -0.000000 0.000000</pose>
      <parent>r_gripper_motor_slider_link</parent>
      <child>r_gripper_motor_screw_link</child>
      <axis>
        <dynamics>
          <damping>0.000100</damping>
          <friction>0.000000</friction>
        </dynamics>
        <limit>
          <lower>-10000000000000000.000000</lower>
          <upper>10000000000000000.000000</upper>
          <effort>0.000000</effort>
          <velocity>0.000000</velocity>
        </limit>
        <xyz>0.000000 1.000000 0.000000</xyz>
      </axis>
    </joint>
    <joint name='r_gripper_r_finger_joint' type='revolute'>
      <pose>0.000000 0.000000 0.000000 0.000000 -0.000000 0.000000</pose>
      <parent>r_wrist_roll_link</parent>
      <child>r_gripper_r_finger_link</child>
      <axis>
        <dynamics>
          <damping>0.020000</damping>
          <friction>0.000000</friction>
        </dynamics>
        <limit>
          <lower>0.000000</lower>
          <upper>0.548000</upper>
          <effort>0.000000</effort>
          <velocity>0.000000</velocity>
        </limit>
        <xyz>0.000000 0.000000 -1.000000</xyz>
      </axis>
    </joint>
    <joint name='r_gripper_r_finger_tip_joint' type='revolute'>
      <pose>0.000000 0.000000 0.000000 0.000000 -0.000000 0.000000</pose>
      <parent>r_gripper_r_finger_link</parent>
      <child>r_gripper_r_finger_tip_link</child>
      <axis>
        <dynamics>
          <damping>0.001000</damping>
          <friction>0.000000</friction>
        </dynamics>
        <limit>
          <lower>0.000000</lower>
          <upper>0.548000</upper>
          <effort>0.000000</effort>
          <velocity>0.000000</velocity>
        </limit>
        <xyz>0.000000 0.000000 1.000000</xyz>
      </axis>
    </joint>
    <joint name='r_gripper_r_screw_screw_joint' type='screw'>
      <pose>0.000000 0.000000 0.000000 0.000000 -0.000000 0.000000</pose>
      <parent>r_gripper_r_finger_tip_link</parent>
      <child>r_gripper_motor_screw_link</child>
      <thread_pitch>-3141.600000</thread_pitch>
      <axis>
        <dynamics>
          <damping>0.000000</damping>
          <friction>0.000000</friction>
        </dynamics>
        <limit>
          <lower>-10000000000000000.000000</lower>
          <upper>10000000000000000.000000</upper>
          <effort>0.000000</effort>
          <velocity>0.000000</velocity>
        </limit>
        <xyz>0.000000 1.000000 0.000000</xyz>
      </axis>
    </joint>
    <joint name='r_gripper_l_screw_screw_joint' type='screw'>
      <pose>0.000000 0.000000 0.000000 0.000000 -0.000000 0.000000</pose>
      <parent>r_gripper_l_finger_tip_link</parent>
      <child>r_gripper_motor_screw_link</child>
      <thread_pitch>3141.600000</thread_pitch>
      <axis>
        <dynamics>
          <damping>0.000000</damping>
          <friction>0.000000</friction>
        </dynamics>
        <limit>
          <lower>-10000000000000000.000000</lower>
          <upper>10000000000000000.000000</upper>
          <effort>0.000000</effort>
          <velocity>0.000000</velocity>
        </limit>
        <xyz>0.000000 1.000000 0.000000</xyz>
      </axis>
    </joint>
    <joint name='r_gripper_r_parallel_root_joint' type='revolute'>
      <pose>0.058910 -0.031000 0.000000 0.000000 -0.000000 0.000000</pose>
      <parent>r_gripper_r_parallel_link</parent>
      <child>r_wrist_roll_link</child>
      <axis>
        <dynamics>
          <damping>0.200000</damping>
          <friction>0.000000</friction>
        </dynamics>
        <limit>
          <lower>-10000000000000000.000000</lower>
          <upper>10000000000000000.000000</upper>
          <effort>0.000000</effort>
          <velocity>0.000000</velocity>
        </limit>
        <xyz>0.000000 0.000000 -1.000000</xyz>
      </axis>
    </joint>
    <joint name='r_gripper_l_parallel_root_joint' type='revolute'>
      <pose>0.058910 0.031000 0.000000 0.000000 -0.000000 0.000000</pose>
      <parent>r_gripper_l_parallel_link</parent>
      <child>r_wrist_roll_link</child>
      <axis>
        <dynamics>
          <damping>0.200000</damping>
          <friction>0.000000</friction>
        </dynamics>
        <limit>
          <lower>-10000000000000000.000000</lower>
          <upper>10000000000000000.000000</upper>
          <effort>0.000000</effort>
          <velocity>0.000000</velocity>
        </limit>
        <xyz>0.000000 0.000000 1.000000</xyz>
      </axis>
    </joint>
    <joint name='r_gripper_r_parallel_tip_joint' type='revolute'>
      <pose>-0.018000 -0.021000 0.000000 0.000000 -0.000000 0.000000</pose>
      <parent>r_gripper_r_parallel_link</parent>
      <child>r_gripper_r_finger_tip_link</child>
      <axis>
        <dynamics>
          <damping>0.000000</damping>
          <friction>0.000000</friction>
        </dynamics>
        <limit>
          <lower>-10000000000000000.000000</lower>
          <upper>10000000000000000.000000</upper>
          <effort>0.000000</effort>
          <velocity>0.000000</velocity>
        </limit>
        <xyz>0.000000 0.000000 1.000000</xyz>
      </axis>
    </joint>
    <joint name='r_gripper_l_parallel_tip_joint' type='revolute'>
      <pose>-0.018000 0.021000 0.000000 0.000000 -0.000000 0.000000</pose>
      <parent>r_gripper_l_parallel_link</parent>
      <child>r_gripper_l_finger_tip_link</child>
      <axis>
        <dynamics>
          <damping>0.000000</damping>
          <friction>0.000000</friction>
        </dynamics>
        <limit>
          <lower>-10000000000000000.000000</lower>
          <upper>10000000000000000.000000</upper>
          <effort>0.000000</effort>
          <velocity>0.000000</velocity>
        </limit>
        <xyz>0.000000 0.000000 1.000000</xyz>
      </axis>
    </joint>
    <joint name='r_gripper_joint' type='prismatic'>
      <pose>0.000000 0.000000 0.000000 0.000000 -0.000000 0.000000</pose>
      <parent>r_gripper_r_finger_tip_link</parent>
      <child>r_gripper_l_finger_tip_link</child>
      <axis>
        <dynamics>
          <damping>0.000000</damping>
          <friction>0.000000</friction>
        </dynamics>
        <limit>
          <lower>-10000000000000000.000000</lower>
          <upper>10000000000000000.000000</upper>
          <effort>0.000000</effort>
          <velocity>0.000000</velocity>
        </limit>
        <xyz>0.000000 1.000000 0.000000</xyz>
      </axis>
    </joint>

<!-- HERE STARTS UPPER BODY   --> 
    <link name="upper_link_bl">
      <pose>-0.228000 0.158000 -0.034000 0 0.5236 0</pose>
      <self_collide>0</self_collide>
      <inertial>
        <pose>0 0 0.5  0 0 0</pose>
      </inertial>
      <visual name="vis_cylinder">
        <pose>0 0 0.25  0 0 0</pose>
        <geometry>
          <cylinder>
            <radius>0.02</radius>
            <length>0.45</length>
          </cylinder>
        </geometry>
        <material>
          <script>
            <uri>file://media/materials/scripts/gazebo.material</uri>
            <name>Gazebo/Grey</name>
          </script>
        </material>
      </visual>
        <collision name="col_cylinder">
        <pose>0 0 0.25  0 0 0</pose>
        <geometry>
          <cylinder>
            <radius>0.02</radius>
            <length>0.45</length>
          </cylinder>
        </geometry>
      </collision>
    </link>
    <link name="upper_link_br">
      <pose>-0.228000 -0.158000 -0.034000 0 0.5236 0</pose>
      <self_collide>0</self_collide>
      <inertial>
        <pose>0 0 0.5  0 0 0</pose>
      </inertial>
      <visual name="vis_cylinder_br">
        <pose>0 0 0.25  0 0 0</pose>
        <geometry>
          <cylinder>
            <radius>0.02</radius>
            <length>0.45</length>
          </cylinder>
        </geometry>
        <material>
          <script>
            <uri>file://media/materials/scripts/gazebo.material</uri>
            <name>Gazebo/Grey</name>
          </script>
        </material>
      </visual>
        <collision name="col_cylinder_br">
        <pose>0 0 0.25  0 0 0</pose>
        <geometry>
          <cylinder>
            <radius>0.02</radius>
            <length>0.45</length>
          </cylinder>
        </geometry>
      </collision>
    </link>
    <link name="upper_link_fl">
      <pose>0.228000 0.158000 -0.034000 0 -0.5236 0</pose>
      <self_collide>0</self_collide>
      <inertial>
        <pose>0 0 0.5  0 0 0</pose>
      </inertial>
      <visual name="vis_cylinder_fl">
        <pose>0 0 0.25  0 0 0</pose>
        <geometry>
          <cylinder>
            <radius>0.02</radius>
            <length>0.45</length>
          </cylinder>
        </geometry>
        <material>
          <script>
            <uri>file://media/materials/scripts/gazebo.material</uri>
            <name>Gazebo/Grey</name>
          </script>
        </material>
      </visual>
        <collision name="col_cylinder_fl">
        <pose>0 0 0.25  0 0 0</pose>
        <geometry>
          <cylinder>
            <radius>0.02</radius>
            <length>0.45</length>
          </cylinder>
        </geometry>
      </collision>
    </link>
    <link name="upper_link_fr">
      <pose>0.228000 -0.158000 -0.034000 0 -0.5236 0</pose>
      <self_collide>0</self_collide>
      <inertial>
        <pose>0 0 0.5  0 0 0</pose>
      </inertial>
      <visual name="vis_cylinder_fr">
        <pose>0 0 0.25  0 0 0</pose>
        <geometry>
          <cylinder>
            <radius>0.02</radius>
            <length>0.45</length>
          </cylinder>
        </geometry>
        <material>
          <script>
            <uri>file://media/materials/scripts/gazebo.material</uri>
            <name>Gazebo/Grey</name>
          </script>
        </material>
      </visual>
        <collision name="col_cylinder_fr">
        <pose>0 0 0.25  0 0 0</pose>
        <geometry>
          <cylinder>
            <radius>0.02</radius>
            <length>0.45</length>
          </cylinder>
        </geometry>
      </collision>
    </link>
    <link name="quer_stange_oben">
      <pose>0.000 0.158000 0.3949 1.57 0 0</pose>
      <self_collide>0</self_collide>
      <inertial>
        <pose>0 0 0.5  0 0 0</pose>
      </inertial>
      <visual name="vis_quer_stange_oben">
        <pose>0 0 0.158  0 0 0</pose>
        <geometry>
          <cylinder>
            <radius>0.02</radius>
            <length>0.316</length>
          </cylinder>
        </geometry>
        <material>
          <script>
            <uri>file://media/materials/scripts/gazebo.material</uri>
            <name>Gazebo/Grey</name>
          </script>
        </material>
      </visual>
        <collision name="col_quer_stange_oben">
        <pose>0 0 0.158  0 0 0</pose>
        <geometry>
          <cylinder>
            <radius>0.006</radius>
            <length>0.316</length>
          </cylinder>
        </geometry>
      </collision>
    </link>
<!-- HERE starts the hanging part -->
<!-- torso -->
    <link name='torso_lift_motor_screw_link'>
      <self_collide>0</self_collide>
      <pose>-0.150000 0.000000 0.751000 0.000000 -0.000000 0.000000</pose>
      <inertial>
        <mass>1.000000</mass>
        <inertia>
          <ixx>0.001000</ixx>
          <ixy>0.000000</ixy>
          <ixz>0.000000</ixz>
          <iyy>0.001000</iyy>
          <iyz>0.000000</iyz>
          <izz>0.001000</izz>
        </inertia>
      </inertial>
      <velocity_decay/>
    </link>
   <link name='torso_lift_link'>
      <self_collide>0</self_collide>
      <pose>-0.050000 0.12000000 0.790675 0.000000 -0.000000 0.000000</pose>
      <inertial>
        <mass>2.0</mass>
        <pose>-0.099499 -0.000004 -0.086764 0.000000 -0.000000 0.000000</pose>
        <inertia>
          <ixx>2.792330</ixx>
          <ixy>0.004280</ixy>
          <ixz>-0.160631</ixz>
          <iyy>2.521060</iyy>
          <iyz>0.029689</iyz>
          <izz>0.536551</izz>
        </inertia>
      </inertial>
      <collision name='torso_lift_link_geom'>
        <geometry>
	  <cylinder>
            <radius>0.02</radius>
            <length>1.3</length>
         </cylinder>
        </geometry>
      </collision>
      <visual name='torso_lift_link_geom_visual'>
        <pose>0 0 0.0 0 0 0</pose>
        <geometry>
          <cylinder>
            <radius>0.02</radius>
            <length>1.3</length>
          </cylinder>
        </geometry>
        <material>
          <script>
            <uri>file://media/materials/scripts/gazebo.material</uri>
            <name>Gazebo/Grey</name>
          </script>
        </material>
      </visual>
      <sensor name='torso_lift_contact_sensor' type='contact'>
        <update_rate>100.000000</update_rate>
        <contact>
          <collision>torso_lift_link_geom</collision>
          <topic>__default_topic__</topic>
        </contact>
      </sensor>
      <velocity_decay/>
    </link>
   <link name='torso_lift_link_r'>
      <self_collide>0</self_collide>
      <pose>-0.050000 -0.12000000 0.790675 0.000000 -0.000000 0.000000</pose>
      <inertial>
        <mass>2.0</mass>
        <pose>-0.099499 -0.000004 -0.086764 0.000000 -0.000000 0.000000</pose>
        <inertia>
          <ixx>2.792330</ixx>
          <ixy>0.004280</ixy>
          <ixz>-0.160631</ixz>
          <iyy>2.521060</iyy>
          <iyz>0.029689</iyz>
          <izz>0.536551</izz>
        </inertia>
      </inertial>
      <collision name='torso_lift_link_geom_r'>
        <geometry>
	  <cylinder>
            <radius>0.02</radius>
            <length>1.3</length>
         </cylinder>
        </geometry>
      </collision>
      <visual name='torso_lift_link_geom_visual_r'>
        <pose>0 0 0.0 0 0 0</pose>
        <geometry>
          <cylinder>
            <radius>0.02</radius>
            <length>1.3</length>
          </cylinder>
        </geometry>
        <material>
          <script>
            <uri>file://media/materials/scripts/gazebo.material</uri>
            <name>Gazebo/Grey</name>
          </script>
        </material>
      </visual>
      <sensor name='torso_lift_contact_sensor_r' type='contact'>
        <update_rate>100.000000</update_rate>
        <contact>
          <collision>torso_lift_link_geom</collision>
          <topic>__default_topic__</topic>
        </contact>
      </sensor>
      <velocity_decay/>
    </link>
<!-- x gripper -->
    <link name='arm_x_ext'>
      <self_collide>0</self_collide>
      <pose>-0.050000 0.0000000 1.3 0.000000 -0.000000 0.000000</pose>
      <inertial>
        <mass>2.0</mass>
      </inertial>
      <collision name='col_arm_x_ext'>
        <pose>-0.15 0.0 0.0 0 0 0</pose>
        <geometry>
          <box>
            <size>0.3 0.2 0.03</size>
          </box>
        </geometry>
      </collision>
      <visual name='vis_arm_x_ext'>
        <pose>-0.15 0.0 0.0 0 0 0</pose>
        <geometry>
          <box>
            <size>0.3 0.2 0.03</size>
          </box>
        </geometry>
        <material>
          <script>
            <uri>file://media/materials/scripts/gazebo.material</uri>
            <name>Gazebo/Grey</name>
          </script>
        </material>
      </visual>
      <velocity_decay/>
    </link>
<!-- y gripper -->

<!-- lower puller -->
<!-- battery -->
    <link name="cyl_hang_bl">
      <pose>-0.152000 0.128000 0.135 0 0.5236 0</pose>
      <self_collide>0</self_collide>
      <inertial>
        <pose>0 0 0.5  0 0 0</pose>
      </inertial>
      <visual name="vis_cyl_hang_bl">
        <pose>0 0 0.15  0 0 0</pose>
        <geometry>
          <cylinder>
            <radius>0.01</radius>
            <length>0.3</length>
          </cylinder>
        </geometry>
        <material>
          <script>
            <uri>file://media/materials/scripts/gazebo.material</uri>
            <name>Gazebo/Grey</name>
          </script>
        </material>
      </visual>
        <collision name="col_cyl_hang_bl">
        <pose>0 0 0.15  0 0 0</pose>
        <geometry>
          <cylinder>
            <radius>0.01</radius>
            <length>0.3</length>
          </cylinder>
        </geometry>
      </collision>
    </link>
    <link name="cyl_hang_br">
      <pose>-0.152000 -0.128000 0.135 0 0.5236 0</pose>
      <self_collide>0</self_collide>
      <inertial>
        <pose>0 0 0.5  0 0 0</pose>
      </inertial>
      <visual name="vis_cyl_hang_br">
        <pose>0 0 0.15  0 0 0</pose>
        <geometry>
          <cylinder>
            <radius>0.01</radius>
            <length>0.30</length>
          </cylinder>
        </geometry>
        <material>
          <script>
            <uri>file://media/materials/scripts/gazebo.material</uri>
            <name>Gazebo/Grey</name>
          </script>
        </material>
      </visual>
        <collision name="col_cyl_hang_br">
        <pose>0 0 0.15  0 0 0</pose>
        <geometry>
          <cylinder>
            <radius>0.01</radius>
            <length>0.30</length>
          </cylinder>
        </geometry>
      </collision>
    </link>
    <link name="cyl_hang_fl">
      <pose>0.152000 0.128000 0.135 0 -0.5236 0</pose>
      <self_collide>0</self_collide>
      <inertial>
        <pose>0 0 0.5  0 0 0</pose>
      </inertial>
      <visual name="vis_cyl_hang_fl">
        <pose>0 0 0.15  0 0 0</pose>
        <geometry>
          <cylinder>
            <radius>0.01</radius>
            <length>0.30</length>
          </cylinder>
        </geometry>
        <material>
          <script>
            <uri>file://media/materials/scripts/gazebo.material</uri>
            <name>Gazebo/Grey</name>
          </script>
        </material>
      </visual>
        <collision name="col_cyl_hang_fl">
        <pose>0 0 0.15  0 0 0</pose>
        <geometry>
          <cylinder>
            <radius>0.01</radius>
            <length>0.30</length>
          </cylinder>
        </geometry>
      </collision>
    </link>
    <link name="cyl_hang_fr">
      <pose>0.152000 -0.128000 0.135 0 -0.5236 0</pose>
      <self_collide>0</self_collide>
      <inertial>
        <pose>0 0 0.5  0 0 0</pose>
      </inertial>
      <visual name="vis_cyl_hang_fr">
        <pose>0 0 0.15  0 0 0</pose>
        <geometry>
          <cylinder>
            <radius>0.01</radius>
            <length>0.30</length>
          </cylinder>
        </geometry>
        <material>
          <script>
            <uri>file://media/materials/scripts/gazebo.material</uri>
            <name>Gazebo/Grey</name>
          </script>
        </material>
      </visual>
        <collision name="col_cyl_hang_fr">
        <pose>0 0 0.15  0 0 0</pose>
        <geometry>
          <cylinder>
            <radius>0.01</radius>
            <length>0.30</length>
          </cylinder>
        </geometry>
      </collision>
    </link>
    <link name="battery_box">
      <pose>0.0 0.0 0.0725 0 0.0 0</pose>
      <self_collide>0</self_collide>
      <inertial>
        <mass>60.0</mass>
        <pose>0.0 0 0.0 0 0 0</pose>
      </inertial>
      <visual name="vis_battery_box_fr">
        <pose>0 0 0.0 0 0 0</pose>
        <geometry>
          <box>
            <size>0.304 0.256 0.15000</size>
          </box>
        </geometry>
        <material>
          <script>
            <uri>file://media/materials/scripts/gazebo.material</uri>
            <name>Gazebo/Grey</name>
          </script>
        </material>
      </visual>
        <collision name="col_battery_box_fr">
        <pose>0 0 0.0 0 0 0</pose>
        <geometry>
          <box>
            <size>0.304 0.256 0.15000</size>
          </box>
        </geometry>
      </collision>
    </link>
<!-- JOINTS-->
    <joint name="base_footprint_joint" type="revolute">
      <pose>0 0 0 0 0 0</pose>
      <parent>base_footprint</parent>
      <child>base_link</child>
      <axis>
        <dynamics>
          <damping>0</damping>
          <friction>0</friction>
        </dynamics>
        <limit><lower>0</lower><upper>0</upper><effort>0</effort><velocity>0</velocity></limit>
        <xyz>0 0 1</xyz>
      </axis>
    </joint>
    <joint name="base_laser_front_hokuyo_urg04_laser_joint" type="revolute">
      <pose>0 0 0 0 0 0</pose>
      <parent>base_link</parent>
      <child>base_laser_front_link</child>
      <axis>
        <dynamics>
          <damping>0</damping>
          <friction>0</friction>
        </dynamics>
        <limit><lower>0</lower><upper>0</upper><effort>0</effort><velocity>0</velocity></limit>
        <xyz>0 0 1</xyz>
      </axis>
    </joint>
<!-- xy extension joints -->
    <joint name='extend_x_joint1' type='prismatic'>
      <parent>torso_lift_link</parent>
      <child>arm_x_ext</child>
      <axis>
        <xyz>0.000000 0.000000 1.000000</xyz>
        <limit>
          <lower>0.000000</lower>
          <upper>1.30000</upper>
          <effort>0.000000</effort>
          <velocity>1.000000</velocity>
        </limit>
      </axis>
    </joint>
    <joint name='extend_x_joint2' type='prismatic'>
      <parent>torso_lift_link_r</parent>
      <child>arm_x_ext</child>
      <axis>
        <xyz>0.000000 0.000000 1.000000</xyz>
        <limit>
          <lower>0.000000</lower>
          <upper>1.30000</upper>
          <effort>0.000000</effort>
          <velocity>1.000000</velocity>
        </limit>
      </axis>
    </joint>
<!-- torso joints -->
    <joint name='torso_lift_joint' type='prismatic'>
      <parent>battery_box</parent>
      <child>torso_lift_link</child>
      <axis>
        <xyz>0.000000 0.000000 1.000000</xyz>
        <limit>
          <lower>0.000000</lower>
          <upper>0.00000</upper>
          <effort>0.000000</effort>
          <velocity>4.000000</velocity>
        </limit>
      </axis>
    </joint>
    <joint name='torso_lift_joint_r' type='prismatic'>
      <parent>battery_box</parent>
      <child>torso_lift_link_r</child>
      <axis>
        <xyz>0.000000 0.000000 1.000000</xyz>
        <limit>
          <lower>0.000000</lower>
          <upper>0.00000</upper>
          <effort>0.000000</effort>
          <velocity>4.000000</velocity>
        </limit>
      </axis>
    </joint>
<!-- catapult joints -->
    <joint name="caster_joint_bl" type="revolute">
      <pose>0 0 0 0 0 0</pose>
      <parent>base_link</parent>
      <child>caster_link_bl</child>
      <axis>
        <dynamics>
          <damping>1</damping>
          <friction>0</friction>
        </dynamics>
        <limit><lower>-10000000000000000.000000</lower><upper>10000000000000000.000000</upper><effort>0</effort><velocity>0</velocity></limit>
        <xyz>0 0 1</xyz>
      </axis>
    </joint>
    <joint name="upper_joint_bl" type="revolute">
      <parent>caster_link_bl</parent>
      <child>upper_link_bl</child>
      <axis>
        <xyz>0.0 1.0 0</xyz>
      </axis>
    </joint>
    <joint name="upper_joint_br" type="revolute">
      <parent>caster_link_br</parent>
      <child>upper_link_br</child>
      <axis>
        <xyz>0.0 1.0 0</xyz>
      </axis>
    </joint>
    <joint name="upper_joint_fl" type="revolute">
      <parent>caster_link_fl</parent>
      <child>upper_link_fl</child>
      <axis>
        <xyz>0.0 1.0 0</xyz>
      </axis>
    </joint>
    <joint name="upper_joint_fr" type="revolute">
      <parent>caster_link_fr</parent>
      <child>upper_link_fr</child>
      <axis>
        <xyz>0.0 1.0 0</xyz>
      </axis>
    </joint>
    <joint name="upper_quer_bl" type="revolute">
      <pose>0.000 0.0 0.0 0 0 0</pose>
      <parent>upper_link_bl</parent>
      <child>quer_stange_oben</child>
      <axis>
        <xyz>0.0 1.0 0</xyz>
      </axis>
    </joint>
    <joint name="upper_quer_br" type="revolute">
      <pose>0.0 0.0 0.3160 0 0.0 0</pose>
      <parent>upper_link_br</parent>
      <child>quer_stange_oben</child>
      <axis>
        <xyz>0.0 1.0 0</xyz>
      </axis>
    </joint>
    <joint name="upper_quer_fl" type="revolute">
      <pose>0.000 0.0 0.0 0 0 0</pose>
      <parent>upper_link_fl</parent>
      <child>quer_stange_oben</child>
      <axis>
        <xyz>0.0 1.0 0</xyz>
      </axis>
    </joint>
    <joint name="upper_quer_fr" type="revolute">
      <pose>0.0 0.0 0.3160 0 0 0</pose>
      <parent>upper_link_fr</parent>
      <child>quer_stange_oben</child>
      <axis>
        <xyz>0.0 1.0 0</xyz>
      </axis>
    </joint>
    <joint name="quer_hang_bl" type="revolute">
      <pose>0.000 0.0 0.3 0 0 0</pose>
      <parent>quer_stange_oben</parent>
      <child>cyl_hang_bl</child>
      <axis>
        <xyz>0.0 1.0 0</xyz>
      </axis>
    </joint>
    <joint name="quer_hang_br" type="revolute">
      <pose>0.0 0.0 0.3 0 0.0 0</pose>
      <parent>quer_stange_oben</parent>
      <child>cyl_hang_br</child>
      <axis>
        <xyz>0.0 1.0 0</xyz>
      </axis>
    </joint>
    <joint name="quer_hang_fl" type="revolute">
      <pose>0.0 0.0 0.3 0 0 0</pose>
      <parent>quer_stange_oben</parent>
      <child>cyl_hang_fl</child>
      <axis>
        <xyz>0.0 1.0 0</xyz>
      </axis>
    </joint>
    <joint name="quer_hang_fr" type="revolute">
      <pose>0.0 0.0 0.3 0 0 0</pose>
      <parent>quer_stange_oben</parent>
      <child>cyl_hang_fr</child>
      <axis>
        <xyz>0.0 1.0 0</xyz>
      </axis>
    </joint>
 <joint name="box_hang_bl" type="revolute">
      <pose>0.000 0.0 0.0 0 0 0</pose>
      <parent>battery_box</parent>
      <child>cyl_hang_bl</child>
      <axis>
        <xyz>0.0 1.0 0</xyz>
      </axis>
    </joint>
    <joint name="box_hang_br" type="revolute">
      <pose>0.0 0.0 0.0 0 0.0 0</pose>
      <parent>battery_box</parent>
      <child>cyl_hang_br</child>
      <axis>
        <xyz>0.0 1.0 0</xyz>
      </axis>
    </joint>
    <joint name="box_hang_fl" type="revolute">
      <pose>0.0 0.0 0.0 0 0 0</pose>
      <parent>battery_box</parent>
      <child>cyl_hang_fl</child>
      <axis>
        <xyz>0.0 1.0 0</xyz>
      </axis>
    </joint>
    <joint name="box_hang_fr" type="revolute">
      <pose>0.0 0.0 0.0 0 0 0</pose>
      <parent>battery_box</parent>
      <child>cyl_hang_fr</child>
      <axis>
        <xyz>0.0 1.0 0</xyz>
      </axis>
    </joint>
    <joint name="wheel_joint_bl" type="revolute">
      <pose>0 0 0 0 0 0</pose>
      <parent>caster_link_bl</parent>
      <child>wheel_link_bl</child>
      <axis>
        <dynamics>
          <damping>1</damping>
          <friction>0</friction>
        </dynamics>
        <limit><lower>-10000000000000000.000000</lower><upper>10000000000000000.000000</upper><effort>0</effort><velocity>0</velocity></limit>
        <xyz>0 1.000000 0</xyz>
      </axis>
    </joint>
    <joint name="caster_joint_br" type="revolute">
      <pose>0 0 0 0 0 0</pose>
      <parent>base_link</parent>
      <child>caster_link_br</child>
      <axis>
        <dynamics>
          <damping>1</damping>
          <friction>0</friction>
        </dynamics>
        <limit><lower>-10000000000000000.000000</lower><upper>10000000000000000.000000</upper><effort>0</effort><velocity>0</velocity></limit>
        <xyz>0 0 1</xyz>
      </axis>
    </joint>
    <joint name="wheel_joint_br" type="revolute">
      <pose>0 0 0 0 0 0</pose>
      <parent>caster_link_br</parent>
      <child>wheel_link_br</child>
      <axis>
        <dynamics>
          <damping>1</damping>
          <friction>0</friction>
        </dynamics>
        <limit><lower>-10000000000000000.000000</lower><upper>10000000000000000.000000</upper><effort>0</effort><velocity>0</velocity></limit>
        <xyz>0 1.000000 0</xyz>
      </axis>
    </joint>
    <joint name="caster_joint_fl" type="revolute">
      <pose>0 0 0 0 0 0</pose>
      <parent>base_link</parent>
      <child>caster_link_fl</child>
      <axis>
        <dynamics>
          <damping>1</damping>
          <friction>0</friction>
        </dynamics>
        <limit><lower>-10000000000000000.000000</lower><upper>10000000000000000.000000</upper><effort>0</effort><velocity>0</velocity></limit>
        <xyz>0 0 1</xyz>
      </axis>
    </joint>
    <joint name="wheel_joint_fl" type="revolute">
      <pose>0 0 0 0 0 0</pose>
      <parent>caster_link_fl</parent>
      <child>wheel_link_fl</child>
      <axis>
        <dynamics>
          <damping>1</damping>
          <friction>0</friction>
        </dynamics>
        <limit><lower>-10000000000000000.000000</lower><upper>10000000000000000.000000</upper><effort>0</effort><velocity>0</velocity></limit>
        <xyz>0 1.000000 0</xyz>
      </axis>
    </joint>
    <joint name="caster_joint_fr" type="revolute">
      <pose>0 0 0 0 0 0</pose>
      <parent>base_link</parent>
      <child>caster_link_fr</child>
      <axis>
        <dynamics>
          <damping>1</damping>
          <friction>0</friction>
        </dynamics>
        <limit><lower>-10000000000000000.000000</lower><upper>10000000000000000.000000</upper><effort>0</effort><velocity>0</velocity></limit>
        <xyz>0 0 1</xyz>
      </axis>
    </joint>
    <joint name="wheel_joint_fr" type="revolute">
      <pose>0 0 0 0 0 0</pose>
      <parent>caster_link_fr</parent>
      <child>wheel_link_fr</child>
      <axis>
        <dynamics>
          <damping>1</damping>
          <friction>0</friction>
        </dynamics>
        <limit><lower>-10000000000000000.000000</lower><upper>10000000000000000.000000</upper><effort>0</effort><velocity>0</velocity></limit>
        <xyz>0 1.000000 0</xyz>
      </axis>
    </joint>
    <static>0</static>
  </model>
</sdf>
